<mujoco model="cf2">
  <option integrator="RK4" density="1.225" viscosity="1.8e-5"/>

  <compiler inertiafromgeom="false" meshdir="assets" autolimits="true"/>

  <default>
    <default class="cf2">
      <default class="visual">
        <geom group="2" type="mesh" contype="0" conaffinity="0"/>
      </default>
      <default class="collision">
        <geom group="3" type="mesh"/>
      </default>
      <site group="5"/>
    </default>
  </default>

  <asset>
    <material name="polished_plastic" rgba="0.631 0.659 0.678 1"/>
    <material name="polished_gold" rgba="0.969 0.878 0.6 1"/>
    <material name="medium_gloss_plastic" rgba="0.109 0.184 0.0 1"/>
    <material name="propeller_plastic" rgba="0.792 0.820 0.933 1"/>
    <material name="white" rgba="1 1 1 1"/>
    <material name="body_frame_plastic" rgba="0.102 0.102 0.102 1"/>
    <material name="burnished_chrome" rgba="0.898 0.898 0.898 1"/>

    <mesh file="cf2_0.obj"/>
    <mesh file="cf2_1.obj"/>
    <mesh file="cf2_2.obj"/>
    <mesh file="cf2_3.obj"/>
    <mesh file="cf2_4.obj"/>
    <mesh file="cf2_5.obj"/>
    <mesh file="cf2_6.obj"/>
    <mesh file="cf2_collision_0.obj"/>
    <mesh file="cf2_collision_1.obj"/>
    <mesh file="cf2_collision_2.obj"/>
    <mesh file="cf2_collision_3.obj"/>
    <mesh file="cf2_collision_4.obj"/>
    <mesh file="cf2_collision_5.obj"/>
    <mesh file="cf2_collision_6.obj"/>
    <mesh file="cf2_collision_7.obj"/>
    <mesh file="cf2_collision_8.obj"/>
    <mesh file="cf2_collision_9.obj"/>
    <mesh file="cf2_collision_10.obj"/>
    <mesh file="cf2_collision_11.obj"/>
    <mesh file="cf2_collision_12.obj"/>
    <mesh file="cf2_collision_13.obj"/>
    <mesh file="cf2_collision_14.obj"/>
    <mesh file="cf2_collision_15.obj"/>
    <mesh file="cf2_collision_16.obj"/>
    <mesh file="cf2_collision_17.obj"/>
    <mesh file="cf2_collision_18.obj"/>
    <mesh file="cf2_collision_19.obj"/>
    <mesh file="cf2_collision_20.obj"/>
    <mesh file="cf2_collision_21.obj"/>
    <mesh file="cf2_collision_22.obj"/>
    <mesh file="cf2_collision_23.obj"/>
    <mesh file="cf2_collision_24.obj"/>
    <mesh file="cf2_collision_25.obj"/>
    <mesh file="cf2_collision_26.obj"/>
    <mesh file="cf2_collision_27.obj"/>
    <mesh file="cf2_collision_28.obj"/>
    <mesh file="cf2_collision_29.obj"/>
    <mesh file="cf2_collision_30.obj"/>
    <mesh file="cf2_collision_31.obj"/>
  </asset>

  <worldbody>
    <body name="cf2" pos="0 0 0.1" childclass="cf2">
      <freejoint/>
      <inertial pos="0 0 0" mass="0.027" diaginertia="2.3951e-5 2.3951e-5 3.2347e-5"/>
      <camera name="track" pos="-1 0 .5" xyaxes="0 -1 0 1 0 2" mode="trackcom"/>
      <geom mesh="cf2_0" material="propeller_plastic" class="visual"/>
      <geom mesh="cf2_1" material="medium_gloss_plastic" class="visual"/>
      <geom mesh="cf2_2" material="polished_gold" class="visual"/>
      <geom mesh="cf2_3" material="polished_plastic" class="visual"/>
      <geom mesh="cf2_4" material="burnished_chrome" class="visual"/>
      <geom mesh="cf2_5" material="body_frame_plastic" class="visual"/>
      <geom mesh="cf2_6" material="white" class="visual"/>
      <geom mesh="cf2_collision_0" class="collision"/>
      <geom mesh="cf2_collision_1" class="collision"/>
      <geom mesh="cf2_collision_2" class="collision"/>
      <geom mesh="cf2_collision_3" class="collision"/>
      <geom mesh="cf2_collision_4" class="collision"/>
      <geom mesh="cf2_collision_5" class="collision"/>
      <geom mesh="cf2_collision_6" class="collision"/>
      <geom mesh="cf2_collision_7" class="collision"/>
      <geom mesh="cf2_collision_8" class="collision"/>
      <geom mesh="cf2_collision_9" class="collision"/>
      <geom mesh="cf2_collision_10" class="collision"/>
      <geom mesh="cf2_collision_11" class="collision"/>
      <geom mesh="cf2_collision_12" class="collision"/>
      <geom mesh="cf2_collision_13" class="collision"/>
      <geom mesh="cf2_collision_14" class="collision"/>
      <geom mesh="cf2_collision_15" class="collision"/>
      <geom mesh="cf2_collision_16" class="collision"/>
      <geom mesh="cf2_collision_17" class="collision"/>
      <geom mesh="cf2_collision_18" class="collision"/>
      <geom mesh="cf2_collision_19" class="collision"/>
      <geom mesh="cf2_collision_20" class="collision"/>
      <geom mesh="cf2_collision_21" class="collision"/>
      <geom mesh="cf2_collision_22" class="collision"/>
      <geom mesh="cf2_collision_23" class="collision"/>
      <geom mesh="cf2_collision_24" class="collision"/>
      <geom mesh="cf2_collision_25" class="collision"/>
      <geom mesh="cf2_collision_26" class="collision"/>
      <geom mesh="cf2_collision_27" class="collision"/>
      <geom mesh="cf2_collision_28" class="collision"/>
      <geom mesh="cf2_collision_29" class="collision"/>
      <geom mesh="cf2_collision_30" class="collision"/>
      <geom mesh="cf2_collision_31" class="collision"/>
      <site name="imu"/>
      <site name="actuation"/>

      <!-- ===== Propeller spin bodies (visual only, no physics) ===== -->
      <!-- CF2 arm length ~46mm, props at (±0.033, ±0.033) in body frame -->
      <!-- Each prop spins about its local z-axis (body up-axis) -->
      <!-- prop1: front-right (+x,+y), CCW; prop2: back-left  (-x,-y), CCW -->
      <!-- prop3: front-left  (+x,-y), CW;  prop4: back-right (-x,+y), CW  -->

      <body name="prop1" pos=" 0.033  0.033  0.005" childclass="cf2">
        <inertial pos="0 0 0" mass="0.0001" diaginertia="1e-8 1e-8 1e-8"/>
        <joint name="prop1_joint" type="hinge" axis="0 0 1" limited="false" damping="1e-6" armature="0" frictionloss="0"/>
        <geom type="cylinder" size="0.023 0.001" rgba="0.8 0.8 1.0 0.5" contype="0" conaffinity="0" group="2"/>
        <geom type="box"      size="0.023 0.002 0.001" rgba="0.3 0.3 0.9 0.7" contype="0" conaffinity="0" group="2"/>
        <geom type="box"      size="0.002 0.023 0.001" rgba="0.3 0.3 0.9 0.7" contype="0" conaffinity="0" group="2"
              euler="0 0 45"/>
      </body>

      <body name="prop2" pos="-0.033 -0.033  0.005" childclass="cf2">
        <inertial pos="0 0 0" mass="0.0001" diaginertia="1e-8 1e-8 1e-8"/>
        <joint name="prop2_joint" type="hinge" axis="0 0 1" limited="false" damping="1e-6" armature="0" frictionloss="0"/>
        <geom type="cylinder" size="0.023 0.001" rgba="0.8 0.8 1.0 0.5" contype="0" conaffinity="0" group="2"/>
        <geom type="box"      size="0.023 0.002 0.001" rgba="0.3 0.3 0.9 0.7" contype="0" conaffinity="0" group="2"/>
        <geom type="box"      size="0.002 0.023 0.001" rgba="0.3 0.3 0.9 0.7" contype="0" conaffinity="0" group="2"
              euler="0 0 45"/>
      </body>

      <body name="prop3" pos=" 0.033 -0.033  0.005" childclass="cf2">
        <inertial pos="0 0 0" mass="0.0001" diaginertia="1e-8 1e-8 1e-8"/>
        <joint name="prop3_joint" type="hinge" axis="0 0 -1" limited="false" damping="1e-6" armature="0" frictionloss="0"/>
        <geom type="cylinder" size="0.023 0.001" rgba="0.8 0.8 1.0 0.5" contype="0" conaffinity="0" group="2"/>
        <geom type="box"      size="0.023 0.002 0.001" rgba="0.3 0.3 0.9 0.7" contype="0" conaffinity="0" group="2"/>
        <geom type="box"      size="0.002 0.023 0.001" rgba="0.3 0.3 0.9 0.7" contype="0" conaffinity="0" group="2"
              euler="0 0 45"/>
      </body>

      <body name="prop4" pos="-0.033  0.033  0.005" childclass="cf2">
        <inertial pos="0 0 0" mass="0.0001" diaginertia="1e-8 1e-8 1e-8"/>
        <joint name="prop4_joint" type="hinge" axis="0 0 -1" limited="false" damping="1e-6" armature="0" frictionloss="0"/>
        <geom type="cylinder" size="0.023 0.001" rgba="0.8 0.8 1.0 0.5" contype="0" conaffinity="0" group="2"/>
        <geom type="box"      size="0.023 0.002 0.001" rgba="0.3 0.3 0.9 0.7" contype="0" conaffinity="0" group="2"/>
        <geom type="box"      size="0.002 0.023 0.001" rgba="0.3 0.3 0.9 0.7" contype="0" conaffinity="0" group="2"
              euler="0 0 45"/>
      </body>

    </body>
  </worldbody>

  <actuator>
    <motor class="cf2" ctrlrange="0 0.35" gear="0 0 1 0 0 0" site="actuation" name="body_thrust"/>
    <motor class="cf2" ctrlrange="-1 1" gear="0 0 0 -0.001 0 0" site="actuation" name="x_moment"/>
    <motor class="cf2" ctrlrange="-1 1" gear="0 0 0 0 -0.001 0" site="actuation" name="y_moment"/>
    <motor class="cf2" ctrlrange="-1 1" gear="0 0 0 0 0 -0.001" site="actuation" name="z_moment"/>
    <!-- Propeller spin actuators (visual only — direct torque drive) -->
    <motor name="prop1_spin" joint="prop1_joint" gear="1" ctrlrange="-0.01 0.01"/>
    <motor name="prop2_spin" joint="prop2_joint" gear="1" ctrlrange="-0.01 0.01"/>
    <motor name="prop3_spin" joint="prop3_joint" gear="1" ctrlrange="-0.01 0.01"/>
    <motor name="prop4_spin" joint="prop4_joint" gear="1" ctrlrange="-0.01 0.01"/>
  </actuator>

  <sensor>
    <gyro name="body_gyro" site="imu"/>
    <accelerometer name="body_linacc" site="imu"/>
    <framequat name="body_quat" objtype="site" objname="imu"/>
  </sensor>

  <keyframe>
    <key name="hover" qpos="0 0 0.1 1 0 0 0 0 0 0 0" ctrl="0.26487 0 0 0 200 200 -200 -200"/>
  </keyframe>
</mujoco>
